Workbook

Sheet Portada
B4: Resolución 5018 de 2019
B5: por la cual se establecen lineamientos en Seguridad y Salud en el trabajo en los Procesos de Generación, Transmisión, Distribución y Comercialización de la Energía Eléctrica.
C8: Nombre de la empresa:
C9: Nit de la empresa:
C10: Centro de trabajo al que le aplican la línea basal:
C11: Fecha de realización:
C12: Realizado por:
C13: Cargo:
C14: Asesorado por:
C15: Cargo:
C16: Ciudad:
C17: Departamento de ubicación:
C18: Sector económico:
C19: Clase de riesgo:
B20: “Todos los derechos reservados. El presente documento, su diseño y contenido es para uso exclusivo de los usuarios/clientes de SURA, quienes se encuentran facultados para ajustarlo y modificarlo teniendo en cuenta sus necesidades y particularidades con el fin de cumplir sus obligaciones, razón por la cual se encuentra prohibido cualquier uso diferente, así como su comercialización, reproducción y transmisión sin el permiso previo y escrito de SURA. © Propiedad Intelectual de Seguros de Vida Suramericana S.A., ARL SURA, marzo de 2021”.

Sheet Siglas
A2: Seguros de Vida Suramericana S.A., ARL SURA. © Copyright – Marzo de 2021. Todos los derechos reservados.
A5: SIGLA | B5: DEFINICIÓN
A6: NFPA | B6: NATIONAL FIRE PROTECTION ASSOCIATION
A7: RETIE | B7: REGLAMENTO TÉCNICO DE INSTALACIONES ELÉCTRICAS
A8: SG - SST | B8: SISTEMA DE GESTIÓN EN SEGURIDAD Y SALUD E EL TRABAJO
A9: SENA | B9: SERVICIO NACIONAL DE APRENDIZAJE

Sheet SST sector EL. y Actividades
A5: Seguros de Vida Suramericana S.A., ARL SURA. © Copyright – Marzo de 2021. Todos los derechos reservados.
A6: Resolución 5018 de 2019
A7: N° | B7: ITEM | C7: SST SECTOR ELECTRICO Y ACTIVIDADES RELACIONADAS- Generalidades | I7: Calificación | J7: Puntaje
A8: 1 | B8: Generalidades | C8: Se tiene identificada en la matriz de requisitos la legislación referente a la resolución 6045 del 2014 del Ministerio del Trabajo; LA Resolución 3710 de 2019 del Ministerio de Trabajo, el Decreto Único Reglamentario 1072 de 2015 del Sector Trabajo, en los artículos 2.2.4.6.1, 2.2.4.6.8, el articulo 348 del Código Sustantivo del Trabajo, y el articulo 84 de Ia Ley 9 de 1979? | I8: Cumple totalmente | J8: =IF(I8="No cumple",0,IF(I8="No aplica",2,IF(I8="Cumple totalmente",2,IF(I8="Cumple parcialmente",1)))) -> 2
A9: 2 | B9: Generalidades | C9: Se tiene identificada la Resolución 5018/19 en la matriz de requisitos legales? | I9: No cumple | J9: =IF(I9="No cumple",0,IF(I9="No aplica",2,IF(I9="Cumple totalmente",2,IF(I9="Cumple parcialmente",1)))) -> 0
A10: 3 | B10: Artículo 1 | C10: Se cuenta con Programa para Control del Peligro Eléctrico? | I10: No cumple | J10: =IF(I10="No cumple",0,IF(I10="No aplica",2,IF(I10="Cumple totalmente",2,IF(I10="Cumple parcialmente",1)))) -> 0
A11: 4 | B11: Artículo 1 | C11: Se cuenta con hojas de vida del personal externo que realiza actividades en seguridad y salud en el trabajo? | I11: No aplica | J11: =IF(I11="No cumple",0,IF(I11="No aplica",2,IF(I11="Cumple totalmente",2,IF(I11="Cumple parcialmente",1)))) -> 2
A12: 5 | B12: Artículo 1 | C12: La organización cuenta con procedimientos de perfiles de cargo y se validan las hojas de vida del personal técnico y de seguridad? | I12: Cumple totalmente | J12: =IF(I12="No cumple",0,IF(I12="No aplica",2,IF(I12="Cumple totalmente",2,IF(I12="Cumple parcialmente",1)))) -> 2
A13: 6 | B13: Artículo 2 | C13: La organización cuenta con el procedimiento de habilitación y se encuentra evidenciada la habilitación del personal ? | I13: No cumple | J13: =IF(I13="No cumple",0,IF(I13="No aplica",2,IF(I13="Cumple totalmente",2,IF(I13="Cumple parcialmente",1)))) -> 0
A14: 7 | B14: Artículo 2 | C14: Se realiza formación en Riesgo eléctrico a todo el personal operativo y administrativo? | I14: No cumple | J14: =IF(I14="No cumple",0,IF(I14="No aplica",2,IF(I14="Cumple totalmente",2,IF(I14="Cumple parcialmente",1)))) -> 0
A15: 8 | B15: Artículo 2 | C15: Se cuenta con la autorización para acceder y manipular instalaciones eléctricas? | I15: Cumple parcialmente | J15: =IF(I15="No cumple",0,IF(I15="No aplica",2,IF(I15="Cumple totalmente",2,IF(I15="Cumple parcialmente",1)))) -> 1
A16: 9 | B16: Artículo 3 | C16: Se realiza charla pre operativa en donde se identifiquen responsables, peligros, actividades, niveles de tensión y procedimientos de operación entre otros? | I16: Cumple totalmente | J16: =IF(I16="No cumple",0,IF(I16="No aplica",2,IF(I16="Cumple totalmente",2,IF(I16="Cumple parcialmente",1)))) -> 2
A17: 10 | B17: Artículo 3 | C17: Se cuenta con los equipos y herramientas adecuados para realizar actividades eléctricas según el método de ejecución? | I17: Cumple totalmente | J17: =IF(I17="No cumple",0,IF(I17="No aplica",2,IF(I17="Cumple totalmente",2,IF(I17="Cumple parcialmente",1)))) -> 2
A18: 11 | B18: Artículo 3 | C18: La empresa cuenta con un protocolo de comunicaciones propio o del contratante para mantener la comunicación permanente entre equipos de trabajo y centros de control? | I18: Cumple totalmente | J18: =IF(I18="No cumple",0,IF(I18="No aplica",2,IF(I18="Cumple totalmente",2,IF(I18="Cumple parcialmente",1)))) -> 2
A19: 12 | B19: Artículo 3 | C19: La organización cuenta con un protocolo de comunicaciones interna para manejo de emergencias? | I19: Cumple totalmente | J19: =IF(I19="No cumple",0,IF(I19="No aplica",2,IF(I19="Cumple totalmente",2,IF(I19="Cumple parcialmente",1)))) -> 2
... A39: 32 | B39: Artículo 10 | C39: La organización cuenta con Plan (permiso, descargo, autorización, incidencia) de trabajo para intervenciones eléctricas y se realiza diagnóstico previo para determinar actividades, tiempo y método de trabajo? | I39: Cumple parcialmente | J39: =IF(I39="No cumple",0,IF(I39="No aplica",2,IF(I39="Cumple totalmente",2,IF(I39="Cumple parcialmente",1)))) -> 1
A40: 33 | B40: Artículo 10 | C40: Se realizan las actividades previas a la operación como la reunión pre operativa, se identifican peligros y se realiza el diligenciamiento de los registros por parte del líder ? | I40: Cumple parcialmente | J40: =IF(I40="No cumple",0,IF(I40="No aplica",2,IF(I40="Cumple totalmente",2,IF(I40="Cumple parcialmente",1)))) -> 1 | K40: PUNTAJE OBTENIDO | L40: PUNTAJE MAXIMO | M40: PORCENTAJE
A41: N° | B41: ITEM | C41: SST SECTOR ELECTRICO Y ACTIVIDADES RELACIONADAS- Distancias de seguridad | I41: Calificación | J41: Puntaje | K41: =SUM(J8:J40) -> 38 | L41: 66 | M41: =(K41*100/66)% -> 0.57575758
A42: 1 | B42: Artículo 11 | C42: En la operación se garantiza el cumplimento de las distancias de seguridad a que se refiere el RETIE? | I42: Cumple parcialmente | J42: =IF(I42="No cumple",0,IF(I42="No aplica",2,IF(I42="Cumple totalmente",2,IF(I42="Cumple parcialmente",1)))) -> 1
A43: 2 | B43: Artículo 12 | C43: La organización cuenta con procedimiento para señalización e identificación de fases y estas se encuentran señalizadas e identificadas? | I43: Cumple parcialmente | J43: =IF(I43="No cumple",0,IF(I43="No aplica",2,IF(I43="Cumple totalmente",2,IF(I43="Cumple parcialmente",1)))) -> 1 | K43: PUNTAJE OBTENIDO | L43: PUNTAJE MAXIMO | M43: PORCENTAJE
A44: N° | B44: ITEM | C44: SST SECTOR ELECTRICO Y ACTIVIDADES RELACIONADAS-Transformacion | I44: Calificación | J44: Puntaje | K44: 2 | L44: 4 | M44: =(K44*100/4)% -> 0.5
A45: 1 | B45: Artículo 13 | C45: Para las actividades del proceso de transformación la organización cuenta con procedimientos para la ejecución de Ordenes de Trabajo para el mantenimiento y la operación de todos los equipos.? | I45: Cumple totalmente | J45: =IF(I45="No cumple",0,IF(I45="No aplica",2,IF(I45="Cumple totalmente",2,IF(I45="Cumple parcialmente",1)))) -> 2
A46: 2 | B46: Artículo 13 | C46: Se realiza entrega y devolución de los equipos en la condición operativa indicada en el plan de trabajo aprobado por parte del responsable? | I46: No cumple | J46: =IF(I46="No cumple",0,IF(I46="No aplica",2,IF(I46="Cumple totalmente",2,IF(I46="Cumple parcialmente",1)))) -> 0
A47: 3 | B47: Artículo 13 | C47: Se Dispone de una copia actualizada de los procedimientos de operación de equipos de la Subestación dentro de la instalación, tanto en condiciones normales como de emergencia, incluyendo los pianos eléctricos actualizados correspondientes y los manuales de operación.? | I47: Cumple parcialmente | J47: =IF(I47="No cumple",0,IF(I47="No aplica",2,IF(I47="Cumple totalmente",2,IF(I47="Cumple parcialmente",1)))) -> 1
A48: 4 | B48: Artículo 13 | C48: Los equipos se encuentran plenamente identificados y rotulados para realizar cualquier operación y/o mantenimiento.? | I48: Cumple totalmente | J48: =IF(I48="No cumple",0,IF(I48="No aplica",2,IF(I48="Cumple totalmente",2,IF(I48="Cumple parcialmente",1)))) -> 2
A49: 5 | B49: Artículo 13 | C49: La organización garantiza que el personal no porta dentro de la Subestación elementos metálicos que pongan en riesgo su vida o la de sus acompañantes.? | I49: Cumple totalmente | J49: =IF(I49="No cumple",0,IF(I49="No aplica",2,IF(I49="Cumple totalmente",2,IF(I49="Cumple parcialmente",1)))) -> 2
A50: 6 | B50: Artículo 13 | C50: El personal asignado al desarrollo de actividades complementarias en subestaciones eléctricas, tales como la vigilancia, obras civiles, mantenimiento, aseo, entre otras, recibe acción sobre los peligros y riesgos eléctricos a los cuales estará expuesto en esa instalación, y cuenta con la autorización para su ingreso y la necesidad de la supervisión de los trabajos, si lo requiere, por parte del responsable de validar el cumplimiento de los demás requisitos legales y contractuales.? | I50: No cumple | J50: =IF(I50="No cumple",0,IF(I50="No aplica",2,IF(I50="Cumple totalmente",2,IF(I50="Cumple parcialmente",1)))) -> 0
A51: 7 | B51: Artículo 14 | C51: Las Subestaciones de patio se encuentran recubiertas con una capa de gravilla como medida de protección eléctrica y para permitir que se extinga cualquier incendio ocasionado per derrame de aceite.? | I51: Cumple totalmente | J51: =IF(I51="No cumple",0,IF(I51="No aplica",2,IF(I51="Cumple totalmente",2,IF(I51="Cumple parcialmente",1)))) -> 2
A52: 8 | B52: Artículo 14 | C52: En las subestaciones de patio se mantienen en funcionamiento los drenajes que eviten la acumulación de agua en los patios. Los cárcamos y registros deben contar todos con sus respectivas tapas, en buen estado y puestas en su lugar | I52: Cumple totalmente | J52: =IF(I52="No cumple",0,IF(I52="No aplica",2,IF(I52="Cumple totalmente",2,IF(I52="Cumple parcialmente",1)))) -> 2
A53: 9 | B53: Artículo 14 | C53: Las cercas, mampostería, alambrados y mallas de encerramiento deben estar en buenas condiciones y debidamente conectadas a tierra? | I53: Cumple totalmente | J53: =IF(I53="No cumple",0,IF(I53="No aplica",2,IF(I53="Cumple totalmente",2,IF(I53="Cumple parcialmente",1)))) -> 2
A54: 10 | B54: Artículo 14 | C54: Se realiza el control periódico de plagas, roedores y vegetación, mediante controles químicos o biológicos aplicando la legislación vigente en materia ambiental y de seguridad y salud en el trabajo.? | I54: Cumple totalmente | J54: =IF(I54="No cumple",0,IF(I54="No aplica",2,IF(I54="Cumple totalmente",2,IF(I54="Cumple parcialmente",1)))) -> 2
A55: 11 | B55: Artículo 14 | C55: En ejecución de maniobras en subestaciones siempre se cuenta con un medio de comunicación entre el personal habilitado y centro de control.? | I55: Cumple totalmente | J55: =IF(I55="No cumple",0,IF(I55="No aplica",2,IF(I55="Cumple totalmente",2,IF(I55="Cumple parcialmente",1)))) -> 2
A56: 12 | B56: Artículo 14 | C56: Al retiro de cubiertas, protecciones o frentes muertos de las partes energizadas de los tableros, se delimita el área de trabajo con barreras de seguridad y avisos de peligro, ? | I56: Cumple parcialmente | J56: =IF(I56="No cumple",0,IF(I56="No aplica",2,IF(I56="Cumple totalmente",2,IF(I56="Cumple parcialmente",1)))) -> 1
... A86: 42 | B86: Artículo 21 | C86: En la realización de pruebas de inyección de corriente se confirma que los caminos de corriente se encuentren cerrados (continuidad del circuito) y se Utilizar las puntas de prueba adecuadas y en buen estado; se asegura que los cables no se soltaran en Ia ejecución de la misma.. ? | I86: No aplica | J86: =IF(I86="No cumple",0,IF(I86="No aplica",2,IF(I86="Cumple totalmente",2,IF(I86="Cumple parcialmente",1)))) -> 2
A87: 43 | B87: Artículo 22 | C87: En cámaras de registro y cárcamos se evidencia que no se encuentren inundados y se inspecciona y hace mantenimiento periódico a los drenajes.? | I87: Cumple totalmente | J87: =IF(I87="No cumple",0,IF(I87="No aplica",2,IF(I87="Cumple totalmente",2,IF(I87="Cumple parcialmente",1)))) -> 2 | K87: PUNTAJE OBTENIDO | L87: PUNTAJE MAXIMO | M87: PORCENTAJE
A88: 44 | B88: Artículo 22 | C88: Se realiza el análisis y control de peligros y se aplican los controles necesarios con los conductores energizados; igualmente evaluar y controlar otros posibles peligros (trabajo en alturas, espacios confinados, riesgo biológico, entre otros).? | I88: Cumple totalmente | J88: =IF(I88="No cumple",0,IF(I88="No aplica",2,IF(I88="Cumple totalmente",2,IF(I88="Cumple parcialmente",1)))) -> 2 | K88: =SUM(J45:J88) -> 80 | L88: 88 | M88: =(K88*100/88)% -> 0.90909091
A89: N° | B89: ITEM | C89: SST SECTOR ELECTRICO Y ACTIVIDADES RELACIONADAS-Areas de trabajo | I89: Calificación | J89: Puntaje
A90: 1 | B90: Artículo 23 | C90: Los talleres de mantenimiento cuentan con amplitud, iluminación, ventilación y se encuentran en óptimas Condiciones de orden y aseo, cuentan con equipos para el control de incendios y existe señalización y demarcación. los equipos cuentas con guardas protectoras en los equipos que lo requieran.? | I90: Cumple totalmente | J90: =IF(I90="No cumple",0,IF(I90="No aplica",2,IF(I90="Cumple totalmente",2,IF(I90="Cumple parcialmente",1)))) -> 2
A91: 2 | B91: Artículo 24 | C91: Los laboratorios cuentan con amplitud, iluminación, ventilación y se encuentran en óptimas Condiciones de orden y aseo, cuentan con equipos para el control de incendios y existe señalización y demarcación. los equipos cuentan con guardas protectoras y se realiza la certificación de calibración de los equipos.? | I91: Cumple totalmente | J91: =IF(I91="No cumple",0,IF(I91="No aplica",2,IF(I91="Cumple totalmente",2,IF(I91="Cumple parcialmente",1)))) -> 2
A92: 3 | B92: Artículo 25 | C92: En instalaciones y áreas restringidas se establecen procedimientos que regulen el comportamiento de los trabajadores, así como de las personas advertidas, dentro de sus instalaciones.? | I92: Cumple totalmente | J92: =IF(I92="No cumple",0,IF(I92="No aplica",2,IF(I92="Cumple totalmente",2,IF(I92="Cumple parcialmente",1)))) -> 2
...

Sheet Centrales Térmicas
A2: Seguros de Vida Suramericana S.A., ARL SURA. © Copyright – Marzo de 2021. Todos los derechos reservados.
A6: Resolución 5018 de 2019
A7: N° | B7: ITEM | C7: CENTRAL TERMICA- Generalidades | I7: Calificación | J7: Puntaje
A8: 1 | B8: Artículo 35 - a | C8: ¿Las partes de maquinaria que se encuentren en movimiento permanecen protegidas? o ¿se cuenta con los métodos de control en el medio y distancias de seguridad? | J8: =IF(I8="No cumple",0,IF(I8="No aplica",2,IF(I8="Cumple totalmente",2,IF(I8="Cumple parcialmente",1)))) -> FALSE
A9: 2 | B9: Artículo 35 - b | C9: ¿Las tuberías y equipos cumple con el código de colores? | J9: =IF(I9="No cumple",0,IF(I9="No aplica",2,IF(I9="Cumple totalmente",2,IF(I9="Cumple parcialmente",1)))) -> FALSE
A10: 3 | B10: Artículo 35 - c | C10: ¿Las carátulas y ventanillas de los instrumentos indicadores o controladores se encuentran limpias y en buen estado? | J10: =IF(I10="No cumple",0,IF(I10="No aplica",2,IF(I10="Cumple totalmente",2,IF(I10="Cumple parcialmente",1)))) -> FALSE
A11: 4 | B11: Artículo 35 - d | C11: ¿las tuberías que requieren recubrimiento térmico se encuentran en buen estado? | J11: =IF(I11="No cumple",0,IF(I11="No aplica",2,IF(I11="Cumple totalmente",2,IF(I11="Cumple parcialmente",1)))) -> FALSE
A12: 5 | B12: Artículo 35 - e | C12: ¿Las tuberías se mantienen en buen estado?¿Se controlan la fugas de inmediato? | J12: =IF(I12="No cumple",0,IF(I12="No aplica",2,IF(I12="Cumple totalmente",2,IF(I12="Cumple parcialmente",1)))) -> FALSE
A13: 6 | B13: Artículo 35 - f | C13: ¿La válvulas se mantienen en buen estado y se verifican antes de su operación? | J13: =IF(I13="No cumple",0,IF(I13="No aplica",2,IF(I13="Cumple totalmente",2,IF(I13="Cumple parcialmente",1)))) -> FALSE
A14: 7 | B14: Artículo 35 - g | C14: ¿Se cuenta con un sistema de prueba, monitoreo y alarma para detectar fugas de hidrogeno? | J14: =IF(I14="No cumple",0,IF(I14="No aplica",2,IF(I14="Cumple totalmente",2,IF(I14="Cumple parcialmente",1)))) -> FALSE
A15: 8 | B15: Artículo 35 - g | C15: ¿Se cuenta con procedimientos para el manejo de los cilindros de hidrógeno y programa de verificación periódica de los instrumentos medidores de control y protección del sistema? | J15: =IF(I15="No cumple",0,IF(I15="No aplica",2,IF(I15="Cumple totalmente",2,IF(I15="Cumple parcialmente",1)))) -> FALSE
A16: 9 | B16: Artículo 35 - h | C16: ¿Para labores de mantenimiento que se realicen a equipos que contengan hidrógeno se extrae el gas y se realizar una purga con el fin de verificar ausencia del mismo y se realiza medición atmosférica con equipo especializado? | J16: =IF(I16="No cumple",0,IF(I16="No aplica",2,IF(I16="Cumple totalmente",2,IF(I16="Cumple parcialmente",1)))) -> FALSE
A17: 10 | B17: Artículo 35 - i | C17: ¿En todos los equipos auxiliares cercanos al generador, se controlan los riesgos potenciales generadores de fuego, como fugas de aceites, acumulación de grasas, solventes, instalaciones eléctricas provisionales o en mal estado, procesos de soldadura, entre otros? | J17: =IF(I17="No cumple",0,IF(I17="No aplica",2,IF(I17="Cumple totalmente",2,IF(I17="Cumple parcialmente",1)))) -> FALSE
A18: N° | B18: ITEM | C18: CENTRAL TERMICA- Generación Térmica | I18: Calificación | J18: Puntaje
A19: 1 | B19: Artículo 36 | C19: ¿Se cuenta con indicaciones claras y precisas con respecto a no fumar y encender fuego en cercanía de las áreas de manejo de combustibles líquidos, gas o carbón de acuerdo a la normatividad vigente? | J19: =IF(I19="No cumple",0,IF(I19="No aplica",2,IF(I19="Cumple totalmente",2,IF(I19="Cumple parcialmente",1)))) -> FALSE
A20: 2 | B20: Artículo 36 | C20: ¿Se cuenta con procedimientos para la manipulación e intervención y el tipo de EPP a emplear en las plantas donde se requiera el uso de CO2 e hidrógeno? | J20: =IF(I20="No cumple",0,IF(I20="No aplica",2,IF(I20="Cumple totalmente",2,IF(I20="Cumple parcialmente",1)))) -> FALSE
A21: 3 | B21: Artículo 37 - a | C21: ¿Las fugas o derrames de combustible se reportan, controlan y corrigen de inmediato? | J21: =IF(I21="No cumple",0,IF(I21="No aplica",2,IF(I21="Cumple totalmente",2,IF(I21="Cumple parcialmente",1)))) -> FALSE
A22: 4 | B22: Artículo 37 - b | C22: ¿Se cuenta con procedimientos, permisos especiales para trabajos en caliente, se realiza control y seguimiento estricto a su ejecución? | J22: =IF(I22="No cumple",0,IF(I22="No aplica",2,IF(I22="Cumple totalmente",2,IF(I22="Cumple parcialmente",1)))) -> FALSE
A23: 5 | B23: Artículo 37 - c | C23: ¿Se controlan los límites máximos del nivel de los de tanques de almacenamiento de combustibles? | J23: =IF(I23="No cumple",0,IF(I23="No aplica",2,IF(I23="Cumple totalmente",2,IF(I23="Cumple parcialmente",1)))) -> FALSE
A24: 6 | B24: Artículo 37 - d | C24: ¿Se conecta a tierra el vehículo transportador de combustible y con algún sistema de protección contra incendio en el proceso de cargue y descargue de combustible? | J24: =IF(I24="No cumple",0,IF(I24="No aplica",2,IF(I24="Cumple totalmente",2,IF(I24="Cumple parcialmente",1)))) -> FALSE
A25: 7 | B25: Artículo 37 - e | C25: ¿Se realiza uso exclusivo de equipos de comunicación intrínsecamente seguros? | J25: =IF(I25="No cumple",0,IF(I25="No aplica",2,IF(I25="Cumple totalmente",2,IF(I25="Cumple parcialmente",1)))) -> FALSE
A26: 8 | B26: Artículo 37 - f | C26: ¿Se garantiza que los diques de contención de los tanques de almacenamiento de combustibles no presenten fisuras o grietas? | J26: =IF(I26="No cumple",0,IF(I26="No aplica",2,IF(I26="Cumple totalmente",2,IF(I26="Cumple parcialmente",1)))) -> FALSE
A27: 9 | B27: Artículo 37 - g | C27: ¿Se asegura que los venteos de seguridad o desfogue de los tanques de almacenamiento no estén obstruidos? | J27: =IF(I27="No cumple",0,IF(I27="No aplica",2,IF(I27="Cumple totalmente",2,IF(I27="Cumple parcialmente",1)))) -> FALSE
A28: 10 | B28: Artículo 37 - h | C28: ¿El agua que se sedimenta en el fondo es evacuada periódicamente, evitando acumulaciones.? | J28: =IF(I28="No cumple",0,IF(I28="No aplica",2,IF(I28="Cumple totalmente",2,IF(I28="Cumple parcialmente",1)))) -> FALSE
A29: 11 | B29: Artículo 37 - i | C29: ¿Se cuenta con procedimientos de trabajo en alturas y espacios confinados. Para ingresar a un tanque de combustible? | J29: =IF(I29="No cumple",0,IF(I29="No aplica",2,IF(I29="Cumple totalmente",2,IF(I29="Cumple parcialmente",1)))) -> FALSE
A30: 12 | B30: Artículo 38 - a | C30: ¿Se cuenta con sistemas de corte de flujo para casos de emergencia en el manejo de gas combustible ? | J30: =IF(I30="No cumple",0,IF(I30="No aplica",2,IF(I30="Cumple totalmente",2,IF(I30="Cumple parcialmente",1)))) -> FALSE
... A118: 100 | B118: Artículo 45 | C118: ¿Se cuenta con procedimientos de trabajo seguro para la inspección, operación y mantenimiento de los sistemas de manejo de cenizas volátiles? ¿al igual que los procedimientos para su transporte y disposición final de estos desechos. Teniendo en cuenta aspectos fundamentales tales como reglamentación de trabajo en Alturas, espacios confinados y aquellos que de acuerdo con las normas ambientales son vitales en la preservación y protección del medio ambiente? | J118: =IF(I118="No cumple",0,IF(I118="No aplica",2,IF(I118="Cumple totalmente",2,IF(I118="Cumple parcialmente",1)))) -> FALSE

Sheet C. Hidroeléctricas
A5: Seguros de Vida Suramericana S.A., ARL SURA. © Copyright – Marzo de 2021. Todos los derechos reservados.
A6: Resolución 5018 de 2019
A7: N° | B7: ITEM | C7: CENTRAL HIDROELECTRICA- Generalidades | I7: Calificación | J7: Puntaje
A8: 1 | B8: Artículo 35 - a | C8: ¿Las partes de maquinaria que se encuentren en movimiento permanecen protegidas? o ¿se cuenta con los métodos de control en el medio y distancias de seguridad? | J8: =IF(I8="No cumple",0,IF(I8="No aplica",2,IF(I8="Cumple totalmente",2,IF(I8="Cumple parcialmente",1)))) -> FALSE
A9: 2 | B9: Artículo 35 - b | C9: ¿Las tuberías y equipos cumple con el código de colores? | J9: =IF(I9="No cumple",0,IF(I9="No aplica",2,IF(I9="Cumple totalmente",2,IF(I9="Cumple parcialmente",1)))) -> FALSE
A10: 3 | B10: Artículo 35 - c | C10: ¿Las carátulas y ventanillas de los instrumentos indicadores o controladores se encuentran limpias y en buen estado? | J10: =IF(I10="No cumple",0,IF(I10="No aplica",2,IF(I10="Cumple totalmente",2,IF(I10="Cumple parcialmente",1)))) -> FALSE
A11: 4 | B11: Artículo 35 - d | C11: ¿las tuberías que requieren recubrimiento térmico se encuentran en buen estado? | J11: =IF(I11="No cumple",0,IF(I11="No aplica",2,IF(I11="Cumple totalmente",2,IF(I11="Cumple parcialmente",1)))) -> FALSE
A12: 5 | B12: Artículo 35 - e | C12: ¿Las tuberías se mantienen en buen estado?¿Se controlan la fugas de inmediato? | J12: =IF(I12="No cumple",0,IF(I12="No aplica",2,IF(I12="Cumple totalmente",2,IF(I12="Cumple parcialmente",1)))) -> FALSE
A13: 6 | B13: Artículo 35 - f | C13: ¿La válvulas se mantienen en buen estado y se verifican antes de su operación? | J13: =IF(I13="No cumple",0,IF(I13="No aplica",2,IF(I13="Cumple totalmente",2,IF(I13="Cumple parcialmente",1)))) -> FALSE
A14: 7 | B14: Artículo 35 - g | C14: ¿Se cuenta con un sistema de prueba, monitoreo y alarma para detectar fugas de hidrogeno? | J14: =IF(I14="No cumple",0,IF(I14="No aplica",2,IF(I14="Cumple totalmente",2,IF(I14="Cumple parcialmente",1)))) -> FALSE
A15: 8 | B15: Artículo 35 - g | C15: ¿Se cuenta con procedimientos para el manejo de los cilindros de hidrógeno y programa de verificación periódica de los instrumentos medidores de control y protección del sistema? | J15: =IF(I15="No cumple",0,IF(I15="No aplica",2,IF(I15="Cumple totalmente",2,IF(I15="Cumple parcialmente",1)))) -> FALSE
A16: 9 | B16: Artículo 35 - h | C16: ¿Para labores de mantenimiento que se realicen a equipos que contengan hidrógeno se extrae el gas y se realizar una purga con el fin de verificar ausencia del mismo y se realiza medición atmosférica con equipo especializado? | J16: =IF(I16="No cumple",0,IF(I16="No aplica",2,IF(I16="Cumple totalmente",2,IF(I16="Cumple parcialmente",1)))) -> FALSE
A17: 10 | B17: Artículo 35 - i | C17: ¿En todos los equipos auxiliares cercanos al generador, se controlan los riesgos potenciales generadores de fuego, como fugas de aceites, acumulación de grasas, solventes, instalaciones eléctricas provisionales o en mal estado, procesos de soldadura, entre otros? | J17: =IF(I17="No cumple",0,IF(I17="No aplica",2,IF(I17="Cumple totalmente",2,IF(I17="Cumple parcialmente",1)))) -> FALSE
A18: N° | B18: ITEM | C18: CENTRAL HIDROELECTRICA - Generación Térmica | I18: Calificación | J18: Puntaje
A19: 1 | B19: Artículo 46 - a | C19: ¿El vertedero cuenta con barandas de protección? | J19: =IF(I19="No cumple",0,IF(I19="No aplica",2,IF(I19="Cumple totalmente",2,IF(I19="Cumple parcialmente",1)))) -> FALSE
A20: 2 | B20: Artículo 46 - b | C20: ¿Existe señalización de los niveles del embalse e iluminación para su lectura cuando se requiera hacerlo en horas nocturnas? | J20: =IF(I20="No cumple",0,IF(I20="No aplica",2,IF(I20="Cumple totalmente",2,IF(I20="Cumple parcialmente",1)))) -> FALSE
A21: 3 | B21: Artículo 46 - c | C21: ¿La revisión de compuertas es realizada por personal capacitado.? | J21: =IF(I21="No cumple",0,IF(I21="No aplica",2,IF(I21="Cumple totalmente",2,IF(I21="Cumple parcialmente",1)))) -> FALSE
A22: 4 | B22: Artículo 46 - d | C22: ¿Existen seguros y candados en las casetas de control de las compuertas.? | J22: =IF(I22="No cumple",0,IF(I22="No aplica",2,IF(I22="Cumple totalmente",2,IF(I22="Cumple parcialmente",1)))) -> FALSE
A23: 5 | B23: Artículo 47 - a | C23: ¿Las embarcaciones, son revisadas verificando se encuentren en buenas condiciones antes de cada uso? | J23: =IF(I23="No cumple",0,IF(I23="No aplica",2,IF(I23="Cumple totalmente",2,IF(I23="Cumple parcialmente",1)))) -> FALSE
A24: 6 | B24: Artículo 47 - b | C24: ¿Las embarcaciones tienen pintada claramente en su costado la capacidad en kilogramos y número máximo de personas que pueden abordarla? Las cuales no se sobrepasan | J24: =IF(I24="No cumple",0,IF(I24="No aplica",2,IF(I24="Cumple totalmente",2,IF(I24="Cumple parcialmente",1)))) -> FALSE
A25: 7 | B25: Artículo 47 - c | C25: ¿Se cuenta con igual número de chaleco salvavidas al de su aforo? y no debe permitirse a ninguna persona estar a bordo, sin el chaleco salvavidas | J25: =IF(I25="No cumple",0,IF(I25="No aplica",2,IF(I25="Cumple totalmente",2,IF(I25="Cumple parcialmente",1)))) -> FALSE
A26: 8 | B26: Artículo 47 - d | C26: ¿Se cuenta a bordo con equipo de comunicaciones y recursos para atender emergencias? | J26: =IF(I26="No cumple",0,IF(I26="No aplica",2,IF(I26="Cumple totalmente",2,IF(I26="Cumple parcialmente",1)))) -> FALSE
A27: 9 | B27: Artículo 47 - e | C27: ¿La operación es realizada por personal autorizado, capacitado y certificado por la autoridad competente.? | J27: =IF(I27="No cumple",0,IF(I27="No aplica",2,IF(I27="Cumple totalmente",2,IF(I27="Cumple parcialmente",1)))) -> FALSE
A28: 10 | B28: Artículo 47 - f | C28: ¿Siempre se inicia su uso con los depósitos de combustible llenos? | J28: =IF(I28="No cumple",0,IF(I28="No aplica",2,IF(I28="Cumple totalmente",2,IF(I28="Cumple parcialmente",1)))) -> FALSE
A29: 11 | B29: Artículo 47 - g | C29: ¿Se tiene prohibido fumar o encender fuego? | J29: =IF(I29="No cumple",0,IF(I29="No aplica",2,IF(I29="Cumple totalmente",2,IF(I29="Cumple parcialmente",1)))) -> FALSE
A30: 12 | B30: Artículo 47 - h | C30: El operador de la embarcación es responsable de la seguridad del personal a bordo ¿los ocupantes reciben instrucciones específicas? | J30: =IF(I30="No cumple",0,IF(I30="No aplica",2,IF(I30="Cumple totalmente",2,IF(I30="Cumple parcialmente",1)))) -> FALSE
... A55: 37 | B55: Artículo 50 - d - 4 | C55: ¿Cuando se efectúen trabajos de reparación en el recinto rodete se cuenta con un sistema de extracción de aire? | J55: =IF(I55="No cumple",0,IF(I55="No aplica",2,IF(I55="Cumple totalmente",2,IF(I55="Cumple parcialmente",1)))) -> FALSE

Sheet L. Transmisión
A2: Seguros de Vida Suramericana S.A., ARL SURA. © Copyright – Marzo de 2021. Todos los derechos reservados.
A5: Resolución 5018 de 2019
A6: N° | B6: ITEM | C6: LÍNEAS DE TRANSMISIÓN - Generalidades | I6: Calificación | J6: Puntaje
A7: 1 | B7: Artículo 51 | C7: ¿Se cuenta con los árboles de carga y los límites de tensión máxima de los conductores y herrajes de los conjuntos de tracción? | J7: =IF(I7="No cumple",0,IF(I7="No aplica",2,IF(I7="Cumple totalmente",2,IF(I7="Cumple parcialmente",1)))) -> FALSE
A8: N° | B8: ITEM | C8: LÍNEAS DE TRANSMISIÓN - Construcción de Líneas | I8: Calificación | J8: Puntaje
A9: 2 | B9: Artículo 52 | C9: ¿Se cuenta con los respectivos proyectos y diseños acordes con las normas aplicables de seguridad y RETIE?. | J9: =IF(I9="No cumple",0,IF(I9="No aplica",2,IF(I9="Cumple totalmente",2,IF(I9="Cumple parcialmente",1)))) -> FALSE
A10: 3 | B10: Artículo 52 | C10: ¿Se cuenta con un punto de anclaje que garantice el desarrollo de la labor segura para levantar o hincar la estructura a construir? | J10: =IF(I10="No cumple",0,IF(I10="No aplica",2,IF(I10="Cumple totalmente",2,IF(I10="Cumple parcialmente",1)))) -> FALSE
C11: LÍNEAS DE TRANSMISIÓN- Trabajos sin tensión | I11: Calificación | J11: Puntaje
A12: 4 | B12: Artículo 53 - a | C12: ¿Se realiza apertura de todas las fuentes de energía? | J12: =IF(I12="No cumple",0,IF(I12="No aplica",2,IF(I12="Cumple totalmente",2,IF(I12="Cumple parcialmente",1)))) -> FALSE
A13: 5 | B13: Artículo 53 - a | C13: ¿En los sitios de trabajo donde no es posible verificar físicamente el corte visible, el jefe de trabajo valida y confirma mediante comunicación directa con el responsable de ejecutar las maniobras de operación? | J13: =IF(I13="No cumple",0,IF(I13="No aplica",2,IF(I13="Cumple totalmente",2,IF(I13="Cumple parcialmente",1)))) -> FALSE
A14: 6 | B14: Artículo 53 - b | C14: ¿Se realiza bloqueo o condenación, enclavamiento y señalización de los equipos de corte con los equipos recomendados por el fabricante? | J14: =IF(I14="No cumple",0,IF(I14="No aplica",2,IF(I14="Cumple totalmente",2,IF(I14="Cumple parcialmente",1)))) -> FALSE
A15: 7 | B15: Artículo 53 - c | C15: ¿Se realiza verificación de la ausencia de tensión? Para mejorar la confiabilidad de las medidas de ausencia de tensión en líneas de transmisión, el equipo de medida debe tener un dispositivo autónomo que verifique el correcto funcionamiento del equipo de medida | J15: =IF(I15="No cumple",0,IF(I15="No aplica",2,IF(I15="Cumple totalmente",2,IF(I15="Cumple parcialmente",1)))) -> FALSE
A16: 8 | B16: Artículo 53 - d | C16: ¿Se realiza instalación de sistemas de puesta a tierra y en cortocircuito lo más cerca posible del sitio donde se van a realizar los trabajos? En líneas de transmisión de Alta y Extra Alta Tensión, donde no sea posible hacer el corto circuito entre las fases, en cada sitio de trabajo se pondrá a tierra el conductor donde se está haciendo la intervención, ya sea a la estructura de la torre o al suelo, teniendo presente hacerlo lo más próximo al sitio de trabajo para evitar contactos con potenciales de electricidad estática presentes. | J16: =IF(I16="No cumple",0,IF(I16="No aplica",2,IF(I16="Cumple totalmente",2,IF(I16="Cumple parcialmente",1)))) -> FALSE
A17: 9 | B17: Artículo 53 - d | C17: ¿Los juegos de puesta a tierra de cable y conectores cumplen con las especificaciones de máxima corriente de falla prevista para la Sistemas de Alta Tensión (mínimo 40 kA)? | J17: =IF(I17="No cumple",0,IF(I17="No aplica",2,IF(I17="Cumple totalmente",2,IF(I17="Cumple parcialmente",1)))) -> FALSE
C18: LÍNEAS DE TRANSMISIÓN- Trabajos con tensión | I18: Calificación | J18: Puntaje
A19: 10 | B19: Artículo 54 | C19: ¿Para los trabajos con tensión los trabajadores cuentan con la respectiva habilitación vigente, con plan de trabajo previamente aprobado que describa las actividades paso a paso con las medidas de seguridad necesarias, y con la debida autorización de acuerdo con el procedimiento definido por cada empresa? | J19: =IF(I19="No cumple",0,IF(I19="No aplica",2,IF(I19="Cumple totalmente",2,IF(I19="Cumple parcialmente",1)))) -> FALSE
A20: 11 | B20: Artículo 54 | C20: ¿Se cuenta con plan de emergencia y personas responsables para la atención de primeros auxilios? | J20: =IF(I20="No cumple",0,IF(I20="No aplica",2,IF(I20="Cumple totalmente",2,IF(I20="Cumple parcialmente",1)))) -> FALSE
A21: 12 | B21: Artículo 54 | C21: ¿Antes de todo trabajo el personal ejecutor realiza una reunión previa y una inspección visual para verificar el estado de las instalaciones, los materiales y herramientas colectivas destinadas a la ejecución del mismo?. se debe Verificar visualmente que no existan descargas parciales, en el aislamiento del equipo a intervenir. | J21: =IF(I21="No cumple",0,IF(I21="No aplica",2,IF(I21="Cumple totalmente",2,IF(I21="Cumple parcialmente",1)))) -> FALSE
A22: 13 | B22: Artículo 54 | C22: ¿Para toda intervención de los equipos, de forma previa se realiza coordinación con el personal de protecciones, control y operación de la línea para verificar la seguridad operativa del sistema durante las maniobras y establecer los planes de emergencia operativos? | J22: =IF(I22="No cumple",0,IF(I22="No aplica",2,IF(I22="Cumple totalmente",2,IF(I22="Cumple parcialmente",1)))) -> FALSE
A23: 14 | B23: Artículo 55 | C23: ¿Para realizar trabajos con tensión en transmisión se utilizan solamente las herramientas, equipos diseñados y aprobados para el uso específico? además tener especial cuidado en el cumplimiento de los siguientes aspectos | J23: =IF(I23="No cumple",0,IF(I23="No aplica",2,IF(I23="Cumple totalmente",2,IF(I23="Cumple parcialmente",1)))) -> FALSE
A24: 15 | B24: Artículo 55 - a | C24: ¿Se realizan pruebas de rutina periódicamente para los equipos de trabajo con tensión de acuerdo con los procedimientos normalizados de nivel nacional o internacional?. Las herramientas que presenten valores de prueba fuera de los establecidos por el fabricante deben ser marcadas y retiradas de uso. | J24: =IF(I24="No cumple",0,IF(I24="No aplica",2,IF(I24="Cumple totalmente",2,IF(I24="Cumple parcialmente",1)))) -> FALSE
A25: 16 | B25: Artículo 55 - b | C25: ¿Se conoce la carga máxima mecánica a la tensión, a la flexión y torsión que soportan cada una de las herramientas que se utilicen de acuerdo con las fichas técnicas? nunca se debe sobrepasar esta carga | J25: =IF(I25="No cumple",0,IF(I25="No aplica",2,IF(I25="Cumple totalmente",2,IF(I25="Cumple parcialmente",1)))) -> FALSE
A26: 17 | B26: Artículo 55 - c | C26: ¿Al transportar las herramientas se evita someterlas a cizalladuras o roturas y cubrirlas con lonas u otro material de protección contra golpes y humedad? | J26: =IF(I26="No cumple",0,IF(I26="No aplica",2,IF(I26="Cumple totalmente",2,IF(I26="Cumple parcialmente",1)))) -> FALSE
A27: 18 | B27: Artículo 55 - d | C27: ¿Se colocan siempre las herramientas sobre una lona impermeable, nunca directamente en el suelo o sobre elementos cortantes? | J27: =IF(I27="No cumple",0,IF(I27="No aplica",2,IF(I27="Cumple totalmente",2,IF(I27="Cumple parcialmente",1)))) -> FALSE
A28: 19 | B28: Artículo 55 - e | C28: ¿Para ejecutar trabajos en equipos energizados, se cuenta previamente con la consignación, teniendo bloqueados los recierres en los extremos de alimentación de los circuitos a intervenir y de los que cruzan por debajo del vano o vanos intervenidos? | J28: =IF(I28="No cumple",0,IF(I28="No aplica",2,IF(I28="Cumple totalmente",2,IF(I28="Cumple parcialmente",1)))) -> FALSE
A29: 20 | B29: Artículo 55 - f | C29: ¿El responsable de la operación de la subestación, informa al jefe de trabajo sobre cualquier evento que ocurra en la subestación, para que el jefe de trabajo tome las decisiones pertinentes? | J29: =IF(I29="No cumple",0,IF(I29="No aplica",2,IF(I29="Cumple totalmente",2,IF(I29="Cumple parcialmente",1)))) -> FALSE
A30: 21 | B30: Artículo 55 - g | C30: ¿Se asegura el cumplimiento de las distancias mínimas de seguridad durante la ejecución de los trabajos? no disminuir las distancias de seguridad de acuerdo a la tensión nominal fase. En caso de tener duda de la distancia mínima, utilizar las pértigas aislantes para asegurar que se cumple con la distancia mínima | J30: =IF(I30="No cumple",0,IF(I30="No aplica",2,IF(I30="Cumple totalmente",2,IF(I30="Cumple parcialmente",1)))) -> FALSE
... A33: 24 | B33: Artículo 55 - j | C33: ¿Se realiza medición constante de la humedad relativa y corriente de fuga de los equipos aislados (Plataforma, andamio, escalera o helicóptero).? | J33: =IF(I33="No cumple",0,IF(I33="No aplica",2,IF(I33="Cumple totalmente",2,IF(I33="Cumple parcialmente",1)))) -> FALSE
C34: LÍNEAS DE TRANSMISIÓN-Trabajos con manejo de cargas en alturas y otras condiciones especiales | I34: Calificación | J34: Puntaje
A35: 25 | B35: Artículo 56 - b | C35: ¿Para toda carga que requiera estar suspendida y sometida a tracción mecánica se conoce su peso y volumen? con el objetivo de determinar los equipos y herramientas para su manipulación | J35: =IF(I35="No cumple",0,IF(I35="No aplica",2,IF(I35="Cumple totalmente",2,IF(I35="Cumple parcialmente",1)))) -> FALSE
A36: 26 | B36: Artículo 56-c | C36: ¿Todos los equipos utilizados para manipular una carga tienen un factor de seguridad de por lo menos 2.5 veces el peso de la carga suspendida? | J36: =IF(I36="No cumple",0,IF(I36="No aplica",2,IF(I36="Cumple totalmente",2,IF(I36="Cumple parcialmente",1)))) -> FALSE
A37: 27 | B37: Artículo 56-c | C37: ¿Al momento de utilizar equipos para manipular cargas se hace una inspección con el fin de verificar su estado y condición operativa? | J37: =IF(I37="No cumple",0,IF(I37="No aplica",2,IF(I37="Cumple totalmente",2,IF(I37="Cumple parcialmente",1)))) -> FALSE
A38: 28 | B38: Artículo 56-d | C38: ¿Para pasar herramienta o materiales entre diferentes niveles, se utilizan recipientes sujetados a la estructura para evitar la caída de este y el material que contenga? | J38: =IF(I38="No cumple",0,IF(I38="No aplica",2,IF(I38="Cumple totalmente",2,IF(I38="Cumple parcialmente",1)))) -> FALSE
A39: 29 | B39: Artículo 56 - e | C39: ¿Los elementos utilizados para el izaje de cargas, son independientes de los elementos utilizados para la protección de caída de alturas de las personas? | J39: =IF(I39="No cumple",0,IF(I39="No aplica",2,IF(I39="Cumple totalmente",2,IF(I39="Cumple parcialmente",1)))) -> FALSE
A40: 30 | B40: Artículo 57 - a | C40: ¿En la planeación de los trabajos de montaje y reparación de conductores aéreos se tienen en cuenta las características técnicas del conductor a intervenir, las cargas a las cuales está sometido cada conductor, la capacidad de carga y nivel de seguridad del tipo de estructura a intervenir al igual que las adyacentes? | J40: =IF(I40="No cumple",0,IF(I40="No aplica",2,IF(I40="Cumple totalmente",2,IF(I40="Cumple parcialmente",1)))) -> FALSE
A41: 31 | B41: Artículo 57 - b | C41: ¿Siempre que sea posible, se tiene como primera opción, la posibilidad de ejecutar el trabajo en línea desenergizada y con los conductores en el piso? | J41: =IF(I41="No cumple",0,IF(I41="No aplica",2,IF(I41="Cumple totalmente",2,IF(I41="Cumple parcialmente",1)))) -> FALSE
A42: 32 | B42: Artículo 57 - b | C42: ¿En caso de realizar trabajos en línea energizada se elabora un procedimiento que incluya el análisis de estabilidad mecánica de la estructura y los conductores que serán sometidos a cargas y que proteja contra caídas al personal habilitado? | J42: =IF(I42="No cumple",0,IF(I42="No aplica",2,IF(I42="Cumple totalmente",2,IF(I42="Cumple parcialmente",1)))) -> FALSE
A43: 33 | B43: Artículo 57 - c | C43: Se planea con la debida anticipación y se establecen los procedimientos para el ascenso, descenso y desplazamiento sobre el conductor o conductores y estructuras, al igual que el esquema de protección con línea de vida para el personal habilitado buscando puntos de anclaje diferentes al conductor intervenido, y la selección detallada de los equipos y dispositivos necesarios, así como los criterios y procedimientos para cada etapa del trabajo, las condiciones para un eventual rescate de algún personal habilitado.? | J43: =IF(I43="No cumple",0,IF(I43="No aplica",2,IF(I43="Cumple totalmente",2,IF(I43="Cumple parcialmente",1)))) -> FALSE
A44: 34 | B44: Artículo 58 | C44: ¿La empresa dispone de un procedimiento normalizado para la atención de emergencias donde expliquen los aspectos técnicos, se identifiquen los riesgos y las medidas de prevención y protección para las personas y el medio ambiente? | J44: =IF(I44="No cumple",0,IF(I44="No aplica",2,IF(I44="Cumple totalmente",2,IF(I44="Cumple parcialmente",1)))) -> FALSE
A45: 35 | B45: Artículo 58 | C45: ¿Para los sitios de trabajo donde se han presentado atentados terroristas y se presume existencia de minas antipersona, se solicita a la fuerza pública, que luego de hacer la revisión protocolaria, entregue la zona de trabajo delimitada e imparta las indicaciones para prevenir cualquier accidente con explosivos? | J45: =IF(I45="No cumple",0,IF(I45="No aplica",2,IF(I45="Cumple totalmente",2,IF(I45="Cumple parcialmente",1)))) -> FALSE
...

Sheet Redes de distribución
A2: Seguros de Vida Suramericana S.A., ARL SURA. © Copyright – Marzo de 2021. Todos los derechos reservados.
A5: Resolución 5018 de 2019
A6: N° | B6: ITEM | C6: REDES DE DISTRIBUCIÓN- Generalidades | I6: Calificación | J6: Puntaje
A7: 1 | B7: Artículo 61 - a | C7: ¿El jefe de trabajo, supervisor o coordinador informa a la central, subestación o centro de control correspondiente los trabajos a realizar, asegurando las comunicaciones en doble vía, repitiendo el mensaje? | J7: =IF(I7="No cumple",0,IF(I7="No aplica",2,IF(I7="Cumple totalmente",2,IF(I7="Cumple parcialmente",1)))) -> FALSE
A8: 2 | B8: Artículo 61 - b | C8: ¿Se solicita la normalización del circuito, esperando la confirmación y verificando su funcionamiento? | J8: =IF(I8="No cumple",0,IF(I8="No aplica",2,IF(I8="Cumple totalmente",2,IF(I8="Cumple parcialmente",1)))) -> FALSE
A9: 3 | B9: Artículo 62 | C9: ¿Todo operador de red establece, divulgar y controlar el cumplimiento de los requisitos técnicos y de seguridad que deben tener los terceros (empresas o personas) que interactúen con sus redes o infraestructura.? | J9: =IF(I9="No cumple",0,IF(I9="No aplica",2,IF(I9="Cumple totalmente",2,IF(I9="Cumple parcialmente",1)))) -> FALSE
A10: 4 | B10: Artículo 63 | C10: ¿Se cuenta como mínimo con dos trabajadores laborando en conjunto que cumplan con la normatividad vigente para trabajos en altura? (Resolución 1409 de 1012 o aquellas modifique, adicione o sustituya) | J10: =IF(I10="No cumple",0,IF(I10="No aplica",2,IF(I10="Cumple totalmente",2,IF(I10="Cumple parcialmente",1)))) -> FALSE
A11: 5 | B11: Artículo 64 | C11: ¿Cuando se ejecuten trabajos sobre circuitos que vayan paralelos o se crucen con otros de mayor o menor tensión y no se garanticen las distancias de seguridad establecidas , se desenergizan los circuitos involucrados o se aíslan eléctricamente por medio de cubiertas según el nivel de tensión? Este trabajo debe ser realizado por Grupo de Trabajos con tensión. T.C.T. | J11: =IF(I11="No cumple",0,IF(I11="No aplica",2,IF(I11="Cumple totalmente",2,IF(I11="Cumple parcialmente",1)))) -> FALSE
A12: 6 | B12: Artículo 65 | C12: ¿Se tiene definido el tiempo de espera por la empresa, de acuerdo con las características de los capacitores posterior a la desconexión de los mismos? | J12: =IF(I12="No cumple",0,IF(I12="No aplica",2,IF(I12="Cumple totalmente",2,IF(I12="Cumple parcialmente",1)))) -> FALSE
A13: 7 | B13: Artículo 65 | C13: ¿Se cortocircuitan las terminales y se conecta a tierra la carcasa del capacitor antes de iniciar los trabajos? Los condensadores no se deben abrir con tensión | J13: =IF(I13="No cumple",0,IF(I13="No aplica",2,IF(I13="Cumple totalmente",2,IF(I13="Cumple parcialmente",1)))) -> FALSE
A14: 8 | B14: Artículo 66 | C14: ¿Cuando se va a trabajar un circuito donde se desenergizó a través de la apertura de un reconectador, se asegura que se encuentre bloqueado el cierre remoto y el local.? | J14: =IF(I14="No cumple",0,IF(I14="No aplica",2,IF(I14="Cumple totalmente",2,IF(I14="Cumple parcialmente",1)))) -> FALSE
A15: 9 | B15: Artículo 67 | C15: ¿Cuando se instalen equipos de seccionamiento que no tengan corte visible se garantiza que estos dispongan de mecanismo de corte efectivo para evitar recierres por parte del centro de control? | J15: =IF(I15="No cumple",0,IF(I15="No aplica",2,IF(I15="Cumple totalmente",2,IF(I15="Cumple parcialmente",1)))) -> FALSE
A16: 10 | B16: Artículo 68 | C16: ¿Los cortacircuitos, seccionadores o cuchillas se operan sin carga?, para lo cual se debe solicitar la desenergización del circuito. Si esto no es posible se deben operar utilizando un equipo que extinga el arco. | J16: =IF(I16="No cumple",0,IF(I16="No aplica",2,IF(I16="Cumple totalmente",2,IF(I16="Cumple parcialmente",1)))) -> FALSE
A17: 11 | B17: Artículo 69 | C17: ¿La empresa tiene documentado sus procedimientos para el montaje o desmontaje de los elementos del sistema? en los cuales aparecerá de manera secuencial el orden de conexiones o desconexiones y las acciones a seguir en caso de identificar una condición de riesgo. | J17: =IF(I17="No cumple",0,IF(I17="No aplica",2,IF(I17="Cumple totalmente",2,IF(I17="Cumple parcialmente",1)))) -> FALSE
A18: 12 | B18: Artículo 70 - a | C18: ¿Se cuenta con ayudas mecánicas para el tendido y tensionado de conductores? | J18: =IF(I18="No cumple",0,IF(I18="No aplica",2,IF(I18="Cumple totalmente",2,IF(I18="Cumple parcialmente",1)))) -> FALSE
... A25: 19 | B25: Artículo 71 - c | C25: ¿Se busca y elimina, en la red o en el transformador, la falla que ocasionó la fusión de la protección? | J25: =IF(I25="No cumple",0,IF(I25="No aplica",2,IF(I25="Cumple totalmente",2,IF(I25="Cumple parcialmente",1)))) -> FALSE
A26: N° | B26: ITEM | C26: REDES DE DISTRIBUCIÓN - Trabajos en baja y media tensión | I26: Calificación | J26: Puntaje
A27: 20 | B27: Artículo 72 - a | C27: ¿El operario técnico de trabajos con tensión cumple con el perfil requerido? Experiencia mínima de 2 años en mantenimiento o construcción de redes de media tensión sin tensión La formación para el aspirante debe estar claramente definida en el proceso de habilitación. En el que además deberá estipularse un período de tiempo de trabajo con acompañamiento activo por parte de personal habilitado para TCT no inferior a 120 horas. | J27: =IF(I27="No cumple",0,IF(I27="No aplica",2,IF(I27="Cumple totalmente",2,IF(I27="Cumple parcialmente",1)))) -> FALSE
A28: 21 | B28: Artículo 72 - b | C28: ¿Se establece un método para que el trabajador pase de conformar un equipo de Trabajo con tensión a realizar trabajos en línea desenergizada? Reinducción previa que permita el afianzamiento a los procedimientos y adaptación al trabajo en línea desenergizada; lo anterior debe ser avalado por la empresa | J28: =IF(I28="No cumple",0,IF(I28="No aplica",2,IF(I28="Cumple totalmente",2,IF(I28="Cumple parcialmente",1)))) -> FALSE
A29: 22 | B29: Artículo 72 - c | C29: El personal de Trabajo con tensión recibe una reinducción y actualización anual, específica para esta labor, el total de horas de capacitación debe ser superior a 40 horas. | J29: =IF(I29="No cumple",0,IF(I29="No aplica",2,IF(I29="Cumple totalmente",2,IF(I29="Cumple parcialmente",1)))) -> FALSE
A30: 23 | B30: Artículo 72 - d | C30: ¿Se practican exámenes médicos de ingreso y periódico anual para constatar el estado de salud, condición física y mental y su aptitud para este tipo de trabajo? No son aptos para el oficio personas con marcapasos, prótesis u órtesis metálicas | J30: =IF(I30="No cumple",0,IF(I30="No aplica",2,IF(I30="Cumple totalmente",2,IF(I30="Cumple parcialmente",1)))) -> FALSE
A31: 24 | B31: Artículo 73 - a | C31: ¿El trabajo con tensión se realiza tal y como fue planeado? | J31: =IF(I31="No cumple",0,IF(I31="No aplica",2,IF(I31="Cumple totalmente",2,IF(I31="Cumple parcialmente",1)))) -> FALSE
A32: 25 | B32: Artículo 73 - a | C32: ¿Cualquier variación en lo planeado se explica por el jefe de trabajos de forma detallada al personal, verificando que haya sido entendida? | J32: =IF(I32="No cumple",0,IF(I32="No aplica",2,IF(I32="Cumple totalmente",2,IF(I32="Cumple parcialmente",1)))) -> FALSE
A33: 26 | B33: Artículo 73 - b | C33: ¿Cada integrante del grupo tiene la responsabilidad del cumplimiento de todas las normas de seguridad, procedimientos, técnicas y métodos de trabajo? | J33: =IF(I33="No cumple",0,IF(I33="No aplica",2,IF(I33="Cumple totalmente",2,IF(I33="Cumple parcialmente",1)))) -> FALSE
A34: 27 | B34: Artículo 73 - c | C34: ¿El cubrimiento de las redes se instala progresivamente iniciando por la zona más próxima a las personas habilitadas, sin dejar en su recorrido puntos descubiertos. De igual forma, las cubiertas se retiran a medida que se vaya “saliendo” de la zona de trabajo? | J34: =IF(I34="No cumple",0,IF(I34="No aplica",2,IF(I34="Cumple totalmente",2,IF(I34="Cumple parcialmente",1)))) -> FALSE
A35: 28 | B35: Artículo 73 - d | C35: ¿Se mantienen los equipos y conductores de otras fases, que puedan ser alcanzados en forma accidental o voluntaria, completamente cubiertos? ¿Se asegura que el trabajo únicamente se realiza en una sola fase? | J35: =IF(I35="No cumple",0,IF(I35="No aplica",2,IF(I35="Cumple totalmente",2,IF(I35="Cumple parcialmente",1)))) -> FALSE
A36: 29 | B36: Artículo 73 - e | C36: ¿En los casos de circuitos en postes o estructuras de madera, se tiene en cuenta que todas las partes de madera se encuentran potencialmente a tierra? | J36: =IF(I36="No cumple",0,IF(I36="No aplica",2,IF(I36="Cumple totalmente",2,IF(I36="Cumple parcialmente",1)))) -> FALSE
A37: 30 | B37: Artículo 73 - f | C37: ¿Se prioriza la seguridad por la rapidez en la ejecución de trabajos en labores de mantenimiento de redes en TCT? | J37: =IF(I37="No cumple",0,IF(I37="No aplica",2,IF(I37="Cumple totalmente",2,IF(I37="Cumple parcialmente",1)))) -> FALSE
A38: 31 | B38: Artículo 73 - g | C38: ¿Se tiene prohibido trabajar con la técnica de TCT en un circuito que presente falla? | J38: =IF(I38="No cumple",0,IF(I38="No aplica",2,IF(I38="Cumple totalmente",2,IF(I38="Cumple parcialmente",1)))) -> FALSE
... A47: 40 | B47: Artículo 75 - e | C47: ¿Para el montaje y desmonte de luminarias se garantiza el cumplimiento de las distancias mínimas de seguridad, considerando la longitud del brazo? | J47: =IF(I47="No cumple",0,IF(I47="No aplica",2,IF(I47="Cumple totalmente",2,IF(I47="Cumple parcialmente",1)))) -> FALSE
A48: N° | B48: ITEM | C48: REDES DE DISTRIBUCIÓN - Trabajos en redes de distribución subterráneas | I48: Calificación | J48: Puntaje
A49: 41 | B49: Artículo 76 - a | C49: ¿En instalaciones subterráneas se realiza señalización y demarcación del área de trabajo? | J49: =IF(I49="No cumple",0,IF(I49="No aplica",2,IF(I49="Cumple totalmente",2,IF(I49="Cumple parcialmente",1)))) -> FALSE
A50: 42 | B50: Artículo 76 - b | C50: ¿En instalaciones subterráneas se abre cámara para permitir escape de gases y ventilación natural? | J50: =IF(I50="No cumple",0,IF(I50="No aplica",2,IF(I50="Cumple totalmente",2,IF(I50="Cumple parcialmente",1)))) -> FALSE
A51: 43 | B51: Artículo 76 - c | C51: ¿Se garantiza que el equipo de trabajo cuente con un sistema de monitoreo de gases durante todo el tiempo de permanencia en la cámara subterránea? | J51: =IF(I51="No cumple",0,IF(I51="No aplica",2,IF(I51="Cumple totalmente",2,IF(I51="Cumple parcialmente",1)))) -> FALSE
A52: 44 | B52: Artículo 76 - d | C52: ¿Antes de entrar a una cámara subterránea, su atmósfera interior es evaluada para determinar si existen gases tóxicos, combustibles o inflamables, con niveles por encima de los límites permisibles y la concentración de oxígeno mínima? Si la concentración del gas es superior al valor límite permisible ¿Se implementa un sistema de ventilación forzada continua hasta llegar al nivel permitido? Mientras la concentración de oxígeno esté por fuera de los valores límites permisibles, no se efectuará el trabajo. En todo caso se deberá aplicar la normatividad legal vigente | J52: =IF(I52="No cumple",0,IF(I52="No aplica",2,IF(I52="Cumple totalmente",2,IF(I52="Cumple parcialmente",1)))) -> FALSE
A53: 45 | B53: Artículo 76 - e | C53: ¿Se inspeccionan las condiciones detectando deficiencias en la estructura y otros peligros, con el fin de implementar las medidas que deben adoptarse para evitar accidentes? | J53: =IF(I53="No cumple",0,IF(I53="No aplica",2,IF(I53="Cumple totalmente",2,IF(I53="Cumple parcialmente",1)))) -> FALSE
A54: 46 | B54: Artículo 76 - f | C54: ¿En instalaciones subterráneas se drena cuando exista acumulación de agua? | J54: =IF(I54="No cumple",0,IF(I54="No aplica",2,IF(I54="Cumple totalmente",2,IF(I54="Cumple parcialmente",1)))) -> FALSE
A55: 47 | B55: Artículo 76 - g | C55: ¿Se planea la posible acción de rescate que resulte necesaria, de acuerdo a los riesgos existentes y a las características de la instalación. Se debe garantiza que el equipo de trabajo cuente con un procedimiento de rescate en situaciones de emergencia? | J55: =IF(I55="No cumple",0,IF(I55="No aplica",2,IF(I55="Cumple totalmente",2,IF(I55="Cumple parcialmente",1)))) -> FALSE
A56: 48 | B56: Artículo 76 - h | C56: ¿Previo al ingreso a una cámara subterránea el trabajador tiene un sistema de protección contra caída que permita su rescate desde el exterior en caso de accidente? | J56: =IF(I56="No cumple",0,IF(I56="No aplica",2,IF(I56="Cumple totalmente",2,IF(I56="Cumple parcialmente",1)))) -> FALSE
A57: 49 | B57: Artículo 76 - i | C57: ¿Para ingresar a la cámara de inspección o subestación de sótano se utilizan escaleras de material no conductor que apoye firme y completamente en el piso? No deben utilizarse los cables o estructuras como peldaños para bajar | J57: =IF(I57="No cumple",0,IF(I57="No aplica",2,IF(I57="Cumple totalmente",2,IF(I57="Cumple parcialmente",1)))) -> FALSE
...

Sheet Comercialización
A5: Seguros de Vida Suramericana S.A., ARL SURA. © Copyright – Marzo de 2021. Todos los derechos reservados.
A6: Resolución 5018 de 2019
A7: N° | B7: ITEM | C7: COMERCIALIZACION - Generalidades | I7: Calificación | J7: Puntaje
A8: 1 | B8: Artículo 81 | C8: La organización en las actividades de comercialización cuenta con procedimientos documentados, divulgados y actualizados cada vez que se presenten cambios en procesos, tecnologías, riesgos? | J8: =IF(I8="No cumple",0,IF(I8="No aplica",2,IF(I8="Cumple totalmente",2,IF(I8="Cumple parcialmente",1)))) -> FALSE
A9: 2 | B9: Artículo 81 | C9: La organización para las actividades en las que se manipulen o se trabaje en cercanía de circuitos de media y baja tensión utiliza elementos de protección personal de acuerdo con el nivel de riesgo por contacto directo o indirecto y arco eléctrico.? | J9: =IF(I9="No cumple",0,IF(I9="No aplica",2,IF(I9="Cumple totalmente",2,IF(I9="Cumple parcialmente",1)))) -> FALSE
A10: 3 | B10: Artículo 81 | C10: La organización tiene establecido el uso de herramientas con el aislamiento y dando cumplimiento a la normatividad nacional o internacional vigente (o aquellas que Ia modifique, adicione o sustituya) y los equipos acordes al nivel de tensión que se utilicen? | J10: =IF(I10="No cumple",0,IF(I10="No aplica",2,IF(I10="Cumple totalmente",2,IF(I10="Cumple parcialmente",1)))) -> FALSE
A11: 4 | B11: Artículo 81 | C11: La organización tiene establecido para las actividades que requieran el acceso, contacto, apertura o cierre de circuitos de media tensión, la programación y consignación de elementos de la red con el centro de control? | J11: =IF(I11="No cumple",0,IF(I11="No aplica",2,IF(I11="Cumple totalmente",2,IF(I11="Cumple parcialmente",1)))) -> FALSE
C12: COMERCIALIZACION- Medición, corte, suspensión, reconexión, reinstalación | I12: Calificación | J12: Puntaje
A13: 5 | B13: Artículo 82 | C13: La organización establece para las actividades relacionadas con medición, el diligenciamiento del formato preoperacional en el que se incluyan la identificación de peligros y el establecimiento de controles antes de Ia ejecución de toda actividad? | J13: =IF(I13="No cumple",0,IF(I13="No aplica",2,IF(I13="Cumple totalmente",2,IF(I13="Cumple parcialmente",1)))) -> FALSE
A14: 6 | B14: Artículo 82 | C14: Se realiza el uso adecuado de los elementos de protección personal y elementos de protección contra caídas requeridos de acuerdo al nivel de tensión, y riesgo por arco eléctrico? | J14: =IF(I14="No cumple",0,IF(I14="No aplica",2,IF(I14="Cumple totalmente",2,IF(I14="Cumple parcialmente",1)))) -> FALSE
A15: 7 | B15: Artículo 82 | C15: Las cajas o encerramientos metálicos en los que no se puede evidenciar la puesta a tierra, se considerara como energizadas a la tensión mas alta de los circuitos que contengan. ¿Se realiza la validación? | J15: =IF(I15="No cumple",0,IF(I15="No aplica",2,IF(I15="Cumple totalmente",2,IF(I15="Cumple parcialmente",1)))) -> FALSE
A16: 8 | B16: Artículo 82 | C16: La instalación o retiro de medidores se realiza desconectando previamente Ia carga y usando herramienta aislada, guantes aislados según nivel de tensión y protección para arco eléctrico?. Los conductores eléctricos desconectados se encuentran sin su correspondiente aislamiento? | J16: =IF(I16="No cumple",0,IF(I16="No aplica",2,IF(I16="Cumple totalmente",2,IF(I16="Cumple parcialmente",1)))) -> FALSE
A17: 9 | B17: Artículo 82 | C17: La organización contempla para la instalación de medidores con tensión en la acometida que, primero se conecte a tierra el medidor, posteriormente el neutro y finalmente las fases, una a una, según su marcación? | J17: =IF(I17="No cumple",0,IF(I17="No aplica",2,IF(I17="Cumple totalmente",2,IF(I17="Cumple parcialmente",1)))) -> FALSE
A18: 10 | B18: Artículo 82 | C18: La organización tiene establecido para el retiro de medidores con tensión en la acometida la desconexión de las fases, una a una según su marcación, luego el neutro y finalmente la puesta a tierra? | J18: =IF(I18="No cumple",0,IF(I18="No aplica",2,IF(I18="Cumple totalmente",2,IF(I18="Cumple parcialmente",1)))) -> FALSE
A19: 11 | B19: Artículo 82 | C19: La organización tiene establecido para el retiro de medidor el aislamiento y señalización de los conductores de fase, neutro y tierra, para facilitar su debida identificación en maniobras posteriores.? | J19: =IF(I19="No cumple",0,IF(I19="No aplica",2,IF(I19="Cumple totalmente",2,IF(I19="Cumple parcialmente",1)))) -> FALSE
A20: 12 | B20: Artículo 82 | C20: La organización tiene establecido en el procedimiento de señalización que, toda área de trabajo se señalice y delimite sin ningún tipo de excepción. | J20: =IF(I20="No cumple",0,IF(I20="No aplica",2,IF(I20="Cumple totalmente",2,IF(I20="Cumple parcialmente",1)))) -> FALSE
A21: 13 | B21: Artículo 83 | C21: Para las actividades de corte, suspensión reconexión y reinstalación se contempla en procedimiento de señalización y demarcación de las áreas de trabajo con el fin de aislar la zona de personal ajeno al grupo de trabajo.? | J21: =IF(I21="No cumple",0,IF(I21="No aplica",2,IF(I21="Cumple totalmente",2,IF(I21="Cumple parcialmente",1)))) -> FALSE
A22: 14 | B22: Artículo 83 | C22: La organización establece el procedimiento para realizar la verificación de tensión y corriente al momento de realizar Ia reconexión o Ia reinstalación. | J22: =IF(I22="No cumple",0,IF(I22="No aplica",2,IF(I22="Cumple totalmente",2,IF(I22="Cumple parcialmente",1)))) -> FALSE
